[2024-10-24T16:30:53.259+0000] {taskinstance.py:1103} INFO - Dependencies all met for dep_context=non-requeueable deps ti=<TaskInstance: weather_request_dag.get_weather manual__2024-10-24T16:30:34.821464+00:00 [queued]>
[2024-10-24T16:30:53.270+0000] {taskinstance.py:1103} INFO - Dependencies all met for dep_context=requeueable deps ti=<TaskInstance: weather_request_dag.get_weather manual__2024-10-24T16:30:34.821464+00:00 [queued]>
[2024-10-24T16:30:53.271+0000] {taskinstance.py:1308} INFO - Starting attempt 1 of 1
[2024-10-24T16:30:54.077+0000] {taskinstance.py:1327} INFO - Executing <Task(SimpleHttpOperator): get_weather> on 2024-10-24 16:30:34.821464+00:00
[2024-10-24T16:30:54.084+0000] {standard_task_runner.py:57} INFO - Started process 2065 to run task
[2024-10-24T16:30:54.087+0000] {standard_task_runner.py:84} INFO - Running: ['***', 'tasks', 'run', 'weather_request_dag', 'get_weather', 'manual__2024-10-24T16:30:34.821464+00:00', '--job-id', '83', '--raw', '--subdir', 'DAGS_FOLDER/weather_request_dag.py', '--cfg-path', '/tmp/tmp5dt8l75r']
[2024-10-24T16:30:54.089+0000] {standard_task_runner.py:85} INFO - Job 83: Subtask get_weather
[2024-10-24T16:30:54.152+0000] {task_command.py:410} INFO - Running <TaskInstance: weather_request_dag.get_weather manual__2024-10-24T16:30:34.821464+00:00 [running]> on host 89a5d87e191c
[2024-10-24T16:30:54.261+0000] {taskinstance.py:1547} INFO - Exporting env vars: AIRFLOW_CTX_DAG_OWNER='***' AIRFLOW_CTX_DAG_ID='weather_request_dag' AIRFLOW_CTX_TASK_ID='get_weather' AIRFLOW_CTX_EXECUTION_DATE='2024-10-24T16:30:34.821464+00:00' AIRFLOW_CTX_TRY_NUMBER='1' AIRFLOW_CTX_DAG_RUN_ID='manual__2024-10-24T16:30:34.821464+00:00'
[2024-10-24T16:30:54.261+0000] {http.py:123} INFO - Calling HTTP method
[2024-10-24T16:30:54.279+0000] {base.py:73} INFO - Using connection ID 'http_default' for task execution.
[2024-10-24T16:30:59.381+0000] {http.py:181} ERROR - HTTP error: NOT FOUND
[2024-10-24T16:30:59.381+0000] {http.py:182} ERROR - <!DOCTYPE HTML PUBLIC "-//W3C//DTD HTML 3.2 Final//EN">
<title>404 Not Found</title>
<h1>Not Found</h1>
<p>The requested URL was not found on the server.  If you entered the URL manually please check your spelling and try again.</p>

[2024-10-24T16:30:59.391+0000] {taskinstance.py:1824} ERROR - Task failed with exception
Traceback (most recent call last):
  File "/home/airflow/.local/lib/python3.7/site-packages/airflow/providers/http/hooks/http.py", line 179, in check_response
    response.raise_for_status()
  File "/home/airflow/.local/lib/python3.7/site-packages/requests/models.py", line 1021, in raise_for_status
    raise HTTPError(http_error_msg, response=self)
requests.exceptions.HTTPError: 404 Client Error: NOT FOUND for url: https://www.httpbin.org/https://goweather.herokuapp.com/weather/moscow

During handling of the above exception, another exception occurred:

Traceback (most recent call last):
  File "/home/airflow/.local/lib/python3.7/site-packages/airflow/providers/http/operators/http.py", line 125, in execute
    response = http.run(self.endpoint, self.data, self.headers, self.extra_options)
  File "/home/airflow/.local/lib/python3.7/site-packages/airflow/providers/http/hooks/http.py", line 169, in run
    return self.run_and_check(session, prepped_request, extra_options)
  File "/home/airflow/.local/lib/python3.7/site-packages/airflow/providers/http/hooks/http.py", line 222, in run_and_check
    self.check_response(response)
  File "/home/airflow/.local/lib/python3.7/site-packages/airflow/providers/http/hooks/http.py", line 183, in check_response
    raise AirflowException(str(response.status_code) + ":" + response.reason)
airflow.exceptions.AirflowException: 404:NOT FOUND
[2024-10-24T16:30:59.410+0000] {taskinstance.py:1350} INFO - Marking task as FAILED. dag_id=weather_request_dag, task_id=get_weather, execution_date=20241024T163034, start_date=20241024T163053, end_date=20241024T163059
[2024-10-24T16:30:59.432+0000] {standard_task_runner.py:109} ERROR - Failed to execute job 83 for task get_weather (404:NOT FOUND; 2065)
[2024-10-24T16:30:59.464+0000] {local_task_job_runner.py:225} INFO - Task exited with return code 1
[2024-10-24T16:30:59.479+0000] {taskinstance.py:2653} INFO - 0 downstream tasks scheduled from follow-on schedule check
