[2024-10-26T13:27:33.417+0000] {taskinstance.py:1103} INFO - Dependencies all met for dep_context=non-requeueable deps ti=<TaskInstance: etl_dag.transform_data manual__2024-10-26T13:26:52.139659+00:00 [queued]>
[2024-10-26T13:27:33.427+0000] {taskinstance.py:1103} INFO - Dependencies all met for dep_context=requeueable deps ti=<TaskInstance: etl_dag.transform_data manual__2024-10-26T13:26:52.139659+00:00 [queued]>
[2024-10-26T13:27:33.427+0000] {taskinstance.py:1308} INFO - Starting attempt 1 of 1
[2024-10-26T13:27:33.442+0000] {taskinstance.py:1327} INFO - Executing <Task(PythonOperator): transform_data> on 2024-10-26 13:26:52.139659+00:00
[2024-10-26T13:27:33.447+0000] {standard_task_runner.py:57} INFO - Started process 1347 to run task
[2024-10-26T13:27:33.450+0000] {standard_task_runner.py:84} INFO - Running: ['***', 'tasks', 'run', 'etl_dag', 'transform_data', 'manual__2024-10-26T13:26:52.139659+00:00', '--job-id', '122', '--raw', '--subdir', 'DAGS_FOLDER/etl_dag.py', '--cfg-path', '/tmp/tmpyg9w5t8n']
[2024-10-26T13:27:33.454+0000] {standard_task_runner.py:85} INFO - Job 122: Subtask transform_data
[2024-10-26T13:27:33.513+0000] {task_command.py:410} INFO - Running <TaskInstance: etl_dag.transform_data manual__2024-10-26T13:26:52.139659+00:00 [running]> on host 0036895724d3
[2024-10-26T13:27:33.890+0000] {taskinstance.py:1545} INFO - Exporting env vars: AIRFLOW_CTX_DAG_OWNER='***' AIRFLOW_CTX_DAG_ID='etl_dag' AIRFLOW_CTX_TASK_ID='transform_data' AIRFLOW_CTX_EXECUTION_DATE='2024-10-26T13:26:52.139659+00:00' AIRFLOW_CTX_TRY_NUMBER='1' AIRFLOW_CTX_DAG_RUN_ID='manual__2024-10-26T13:26:52.139659+00:00'
[2024-10-26T13:27:33.915+0000] {taskinstance.py:1824} ERROR - Task failed with exception
Traceback (most recent call last):
  File "/home/airflow/.local/lib/python3.8/site-packages/pandas/core/indexes/base.py", line 3802, in get_loc
    return self._engine.get_loc(casted_key)
  File "pandas/_libs/index.pyx", line 138, in pandas._libs.index.IndexEngine.get_loc
  File "pandas/_libs/index.pyx", line 165, in pandas._libs.index.IndexEngine.get_loc
  File "pandas/_libs/hashtable_class_helper.pxi", line 5745, in pandas._libs.hashtable.PyObjectHashTable.get_item
  File "pandas/_libs/hashtable_class_helper.pxi", line 5753, in pandas._libs.hashtable.PyObjectHashTable.get_item
KeyError: 'date'

The above exception was the direct cause of the following exception:

Traceback (most recent call last):
  File "/home/airflow/.local/lib/python3.8/site-packages/airflow/operators/python.py", line 181, in execute
    return_value = self.execute_callable()
  File "/home/airflow/.local/lib/python3.8/site-packages/airflow/operators/python.py", line 198, in execute_callable
    return self.python_callable(*self.op_args, **self.op_kwargs)
  File "/opt/airflow/dags/etl_dag.py", line 24, in transform_data
    merged_df['date'] = pd.to_datetime(merged_df['date']).dt.strftime('%Y-%m-%d')
  File "/home/airflow/.local/lib/python3.8/site-packages/pandas/core/frame.py", line 3807, in __getitem__
    indexer = self.columns.get_loc(key)
  File "/home/airflow/.local/lib/python3.8/site-packages/pandas/core/indexes/base.py", line 3804, in get_loc
    raise KeyError(key) from err
KeyError: 'date'
[2024-10-26T13:27:33.930+0000] {taskinstance.py:1345} INFO - Marking task as FAILED. dag_id=etl_dag, task_id=transform_data, execution_date=20241026T132652, start_date=20241026T132733, end_date=20241026T132733
[2024-10-26T13:27:33.945+0000] {standard_task_runner.py:104} ERROR - Failed to execute job 122 for task transform_data ('date'; 1347)
[2024-10-26T13:27:33.953+0000] {local_task_job_runner.py:225} INFO - Task exited with return code 1
[2024-10-26T13:27:33.981+0000] {taskinstance.py:2653} INFO - 0 downstream tasks scheduled from follow-on schedule check
